#VRML_SIM R2023b utf8

EXTERNPROTO "https://raw.githubusercontent.com/cyberbotics/webots/R2023b/projects/objects/backgrounds/protos/TexturedBackground.proto"
EXTERNPROTO "https://raw.githubusercontent.com/cyberbotics/webots/R2023b/projects/objects/backgrounds/protos/TexturedBackgroundLight.proto"
EXTERNPROTO "https://raw.githubusercontent.com/cyberbotics/webots/R2023b/projects/objects/floors/protos/RectangleArena.proto"
EXTERNPROTO "https://raw.githubusercontent.com/cyberbotics/webots/R2023b/projects/appearances/protos/BrushedAluminium.proto"
EXTERNPROTO "https://raw.githubusercontent.com/cyberbotics/webots/R2023b/projects/samples/contests/robocup/protos/RobocupSoccerField.proto"

WorldInfo {
  info [
    "Thanks to Mehdi Ghanavati, Shahid Chamran University"
  ]
  title "Omni-wheels"
  basicTimeStep 8
}
Viewpoint {
  orientation -0.5773502691896257 0.5773502691896257 0.5773502691896257 2.0943245915045035
  position -3.29401281001839 -1.0509253108142569 10.537961571923049
  follow "solid"
}
TexturedBackground {
}
TexturedBackgroundLight {
}
RectangleArena {
  floorSize 11 8
  wallAppearance BrushedAluminium {
    colorOverride 0 0 0
  }
}
RobocupSoccerField {
  size "kid"
}
DEF OMNI_WHEELS_4 Robot {
  translation -4.500000247773006 -2.20000001182525 0.06947588915619243
  rotation -1.7892827514855e-06 -5.079470960878387e-06 0.9999999999854987 0.7853996957957237
  children [
    InertialUnit {
      name "IMU"
    }
    DEF SOLID1 Solid {
      rotation 0 0 1 0.7854003061004253
      children [
        DEF WHEEL1 HingeJoint {
          jointParameters HingeJointParameters {
            position -1.8058441887504393e-10
            anchor -0.1 0 0
          }
          device [
            RotationalMotor {
              name "wheel3"
              maxVelocity 40
            }
            PositionSensor {
              name "pw3"
            }
          ]
          endPoint Solid {
            translation -0.18799999999756029 5.097991327202489e-10 1.2929180695860897e-05
            rotation 0.07849333342854536 0.9969146378159603 -3.893003823416297e-05 1.3850867794302085e-06
            children [
              DEF sr1 HingeJoint {
                jointParameters HingeJointParameters {
                  position -126.31891124653298
                  axis 0 1 0
                  anchor -0.02 0 0.05
                }
                endPoint Solid {
                  translation -0.02 0 0.05
                  rotation 8.62579780380106e-16 -1 1.0636623739582173e-15 0.6552051029412418
                  children [
                    DEF r1 Pose {
                      rotation -1 0 0 1.5708
                      children [
                        DEF SMALL_WHEEL_SHAPE Shape {
                          appearance PBRAppearance {
                            baseColor 1 0.752941 0.796078
                            roughness 1
                            metalness 0
                          }
                          geometry Cylinder {
                            height 0.02
                            radius 0.01
                          }
                        }
                      ]
                    }
                  ]
                  name "sr1"
                  boundingObject USE r1
                  physics Physics {
                    density -1
                    mass 0.1
                  }
                  linearVelocity -6.105184183453292e-07 3.3406394629692865e-07 -9.441417042845165e-08
                  angularVelocity 2.959336642565527e-11 -6.649579982445225e-06 -9.274907758591166e-07
                }
              }
              DEF sr2 HingeJoint {
                jointParameters HingeJointParameters {
                  position 145.23932166375795
                  axis 0 -0.707107 0.707107
                  anchor -0.02 0.03535 0.03535
                }
                endPoint Solid {
                  translation -0.02 0.03535 0.03535
                  rotation 0 0.7071067811865476 -0.7071067811865476 5.557125708552127
                  children [
                    DEF r2 Pose {
                      rotation -1 0 0 2.27
                      children [
                        USE SMALL_WHEEL_SHAPE
                      ]
                    }
                  ]
                  name "sr2"
                  boundingObject USE r2
                  physics Physics {
                    density -1
                    mass 0.1
                  }
                  linearVelocity -5.13128476962851e-07 3.7361168484972115e-07 -3.2941122524832293e-07
                  angularVelocity 6.577466964634884e-07 -6.649577203014453e-06 -7.32007661957825e-07
                }
              }
              DEF sr3 HingeJoint {
                jointParameters HingeJointParameters {
                  position 315.6244833338322
                  axis 0 1 0
                  anchor -0.02 0 -0.05
                }
                endPoint Solid {
                  translation -0.02 0 -0.05
                  rotation 0 1 0 1.4652179748528644
                  children [
                    DEF r3 Pose {
                      rotation -1 0 0 1.5708
                      children [
                        USE SMALL_WHEEL_SHAPE
                      ]
                    }
                  ]
                  name "sr3"
                  boundingObject USE r3
                  physics Physics {
                    density -1
                    mass 0.1
                  }
                  linearVelocity -2.834490782623261e-08 3.8022413099818666e-07 -9.25613252178756e-08
                  angularVelocity -3.8020013205242244e-05 -6.648880137890393e-06 -9.274064964324949e-07
                }
              }
              DEF sr4 HingeJoint {
                jointParameters HingeJointParameters {
                  position -195.38392108712313
                  axis 0 -0.707107 0.707107
                  anchor -0.02 -0.03535 -0.03535
                }
                endPoint Solid {
                  translation -0.02 -0.03535 -0.03535
                  rotation 0 -0.7071067811865476 0.7071067811865476 5.67800874262364
                  children [
                    DEF r4 Pose {
                      rotation -1 0 0 2.27
                      children [
                        USE SMALL_WHEEL_SHAPE
                      ]
                    }
                  ]
                  name "sr4"
                  boundingObject USE r4
                  physics Physics {
                    density -1
                    mass 0.1
                  }
                  linearVelocity -4.313536404760147e-08 3.407296945165534e-07 1.4058502206814567e-07
                  angularVelocity 7.412473138957466e-07 -6.649576748498478e-06 -6.485064582636401e-07
                }
              }
              DEF sr5 HingeJoint {
                jointParameters HingeJointParameters {
                  position 147.55102901301012
                  axis 0 0 1
                  anchor -0.02 0.05 0
                }
                endPoint Solid {
                  translation -0.02 0.05 0
                  rotation 0 0 -1 3.245418359299953
                  children [
                    DEF r5 Pose {
                      children [
                        USE SMALL_WHEEL_SHAPE
                      ]
                    }
                  ]
                  name "sr5"
                  boundingObject USE r5
                  physics Physics {
                    density -1
                    mass 0.1
                  }
                  linearVelocity -2.781309774548829e-07 4.03532024973985e-07 -4.2679976082206e-07
                  angularVelocity 4.6226335492140377e-07 -6.649576590510651e-06 1.3679216580104511e-11
                }
              }
              DEF sr6 HingeJoint {
                jointParameters HingeJointParameters {
                  position -154.2668776340013
                  axis 0 0 1
                  anchor -0.02 -0.05 0
                }
                endPoint Solid {
                  translation -0.02 -0.05 0
                  rotation 0 0 -1 3.4704302616912286
                  children [
                    DEF r6 Pose {
                      children [
                        USE SMALL_WHEEL_SHAPE
                      ]
                    }
                  ]
                  name "sr6"
                  boundingObject USE r6
                  physics Physics {
                    density -1
                    mass 0.1
                  }
                  linearVelocity -2.781328634308604e-07 3.108093536033196e-07 2.3797355734879275e-07
                  angularVelocity 4.622633467768508e-07 -6.649576590969164e-06 1.3679216568112764e-11
                }
              }
              DEF sr7 HingeJoint {
                jointParameters HingeJointParameters {
                  position 179.5610923208043
                  axis 0 0.707107 0.707107
                  anchor -0.02 0.03535 -0.03535
                }
                endPoint Solid {
                  translation -0.02 0.03535 -0.03535
                  rotation 0 0.7071067811865476 0.7071067811865476 3.631903719775885
                  children [
                    DEF r7 Pose {
                      rotation -1 0 0 0.76
                      children [
                        USE SMALL_WHEEL_SHAPE
                      ]
                    }
                  ]
                  name "sr7"
                  boundingObject USE r7
                  physics Physics {
                    density -1
                    mass 0.1
                  }
                  linearVelocity -4.3134001917481046e-08 4.0628460466365967e-07 -3.2940971370189173e-07
                  angularVelocity -2.4284260227476667e-07 -6.649579591284546e-06 -2.223849108975782e-07
                }
              }
              DEF sr8 HingeJoint {
                jointParameters HingeJointParameters {
                  position -151.50991554855537
                  axis 0 0.707107 0.707107
                  anchor -0.02 -0.03535 0.03535
                }
                endPoint Solid {
                  translation -0.02 -0.03535 0.03535
                  rotation 5.563580668206997e-16 -0.7071067811865476 -0.7071067811865475 0.7134681762453011
                  children [
                    DEF r8 Pose {
                      rotation -1 0 0 0.76
                      children [
                        USE SMALL_WHEEL_SHAPE
                      ]
                    }
                  ]
                  name "sr8"
                  boundingObject USE r8
                  physics Physics {
                    density -1
                    mass 0.1
                  }
                  linearVelocity -5.131298391044188e-07 3.080567513407169e-07 1.4058351008648236e-07
                  angularVelocity -2.4488174587051755e-07 -6.649579594481211e-06 -2.2034578990464771e-07
                }
              }
              DEF WHEEL_TRANS Pose {
                translation -0.02 0 0
                rotation 0 -1 0 1.5708
                children [
                  DEF WHEEL_SHAPE Shape {
                    appearance PBRAppearance {
                      baseColor 0.678431 0.847059 0.901961
                      roughness 1
                      metalness 0
                    }
                    geometry Cylinder {
                      height 0.02
                      radius 0.05
                      subdivision 20
                    }
                  }
                ]
              }
            ]
            boundingObject Pose {
              translation -0.02 0 0
              rotation 0 -1 0 1.5708
              children [
                DEF wheel1 Shape {
                  appearance PBRAppearance {
                    baseColor 0.8 0.8 0.8
                    transparency 0.12999999523162842
                    roughness 1
                    metalness 0
                    emissiveColor 0 1 0
                  }
                  geometry Cylinder {
                    height 0.02
                    radius 0.05
                  }
                }
              ]
            }
            physics Physics {
            }
            linearVelocity -2.782095121615093e-07 3.572703454854155e-07 -9.443933000535835e-08
            angularVelocity 4.622664590444692e-07 -6.649578392115595e-06 -9.274892374317761e-07
          }
        }
      ]
      name "wheel 1"
      boundingObject DEF DUMMY Sphere {
        radius 0.01
      }
      physics Physics {
      }
    }
    DEF SOLID2 Solid {
      rotation 0 0 1 2.3561996938995744
      children [
        DEF WHEEL2 HingeJoint {
          jointParameters HingeJointParameters {
            position 1.3282820413439712e-06
            anchor -0.1 0 0
          }
          device [
            RotationalMotor {
              name "wheel4"
              maxVelocity 40
            }
            PositionSensor {
              name "pw4"
            }
          ]
          endPoint Solid {
            translation -0.1880000000430867 -5.941673163600374e-10 1.2889234711351008e-05
            rotation -0.9999998355622093 0.0005734762779880488 7.161788723802152e-07 0.0024045216174579816
            children [
              DEF sr1 HingeJoint {
                jointParameters HingeJointParameters {
                  position 281.32831258393514
                  axis 0 1 0
                  anchor -0.02 0 0.05
                }
                endPoint Solid {
                  translation -0.02 0 0.05
                  rotation 0 1 0 4.868159068033339
                  children [
                    USE r1
                  ]
                  name "sr1"
                  boundingObject USE r1
                  physics Physics {
                    density -1
                    mass 0.1
                  }
                  linearVelocity -4.514805474789621e-09 5.635591500525401e-07 1.1943941569018672e-09
                  angularVelocity -6.241978015166974e-06 2.142055254368589e-09 -9.096584211353734e-07
                }
              }
              DEF sr2 HingeJoint {
                jointParameters HingeJointParameters {
                  position -654.5466461268
                  axis 0 -0.707107 0.707107
                  anchor -0.02 0.03535 0.03535
                }
                endPoint Solid {
                  translation -0.02 0.03535 0.03535
                  rotation -9.990132437390992e-16 0.707106781186548 -0.707106781186547 1.0953741801230055
                  children [
                    USE r2
                  ]
                  name "sr2"
                  boundingObject USE r2
                  physics Physics {
                    density -1
                    mass 0.1
                  }
                  linearVelocity -3.657255719230004e-08 4.716086186947485e-07 2.2156723942678973e-07
                  angularVelocity -6.2419831962468976e-06 3.998713042051596e-07 -5.039275829943964e-07
                }
              }
              DEF sr3 HingeJoint {
                jointParameters HingeJointParameters {
                  position -301.8413067568631
                  axis 0 1 0
                  anchor -0.02 0 -0.05
                }
                endPoint Solid {
                  translation -0.02 0 -0.05
                  rotation 0 -1 0 0.24841201224295442
                  children [
                    USE r3
                  ]
                  name "sr3"
                  boundingObject USE r3
                  physics Physics {
                    density -1
                    mass 0.1
                  }
                  linearVelocity -3.904074661039605e-09 2.3571995057175772e-08 -2.9766546561545105e-10
                  angularVelocity -6.241122264043074e-06 -3.8772742851667727e-07 -9.103887577915491e-07
                }
              }
              DEF sr4 HingeJoint {
                jointParameters HingeJointParameters {
                  position 498.1894738431226
                  axis 0 -0.707107 0.707107
                  anchor -0.02 -0.03535 -0.03535
                }
                endPoint Solid {
                  translation -0.02 -0.03535 -0.03535
                  rotation 0 0.7071067811865475 -0.7071067811865475 4.4653507312443335
                  children [
                    USE r4
                  ]
                  name "sr4"
                  boundingObject USE r4
                  physics Physics {
                    density -1
                    mass 0.1
                  }
                  linearVelocity 2.815430450493702e-08 3.148439043757398e-08 -2.2067946908957492e-07
                  angularVelocity -6.241984643592745e-06 5.121998858393373e-07 -3.910572928268391e-07
                }
              }
              DEF sr5 HingeJoint {
                jointParameters HingeJointParameters {
                  position -315.68345521681624
                  axis 0 0 1
                  anchor -0.02 0.05 0
                }
                endPoint Solid {
                  translation -0.02 0.05 0
                  rotation -1.1642276508733631e-15 8.263344095650892e-16 -0.9999999999999999 1.5241898578368904
                  children [
                    USE r5
                  ]
                  name "sr5"
                  boundingObject USE r5
                  physics Physics {
                    density -1
                    mass 0.1
                  }
                  linearVelocity -4.967920902444494e-08 2.5079568652780933e-07 3.1245625367934043e-07
                  angularVelocity -6.24198355902871e-06 -6.114788814788017e-09 -5.3040159798719124e-11
                }
              }
              DEF sr6 HingeJoint {
                jointParameters HingeJointParameters {
                  position 573.4599676906284
                  axis 0 0 1
                  anchor -0.02 -0.05 0
                }
                endPoint Solid {
                  translation -0.02 -0.05 0
                  rotation 0 0 -1 4.59308056989351
                  children [
                    USE r6
                  ]
                  name "sr6"
                  boundingObject USE r6
                  physics Physics {
                    density -1
                    mass 0.1
                  }
                  linearVelocity 4.126095847091049e-08 2.52297300285489e-07 -3.1156848306681865e-07
                  angularVelocity -6.241983559071174e-06 -6.114793028386728e-09 -5.304016993956585e-11
                }
              }
              DEF sr7 HingeJoint {
                jointParameters HingeJointParameters {
                  position -638.5446574111318
                  axis 0 0.707107 0.707107
                  anchor -0.02 0.03535 -0.03535
                }
                endPoint Solid {
                  translation -0.02 0.03535 -0.03535
                  rotation -3.0078192244080785e-16 -0.7071067811865479 -0.7071067811865471 -2.34024392118605
                  children [
                    USE r7
                  ]
                  name "sr7"
                  boundingObject USE r7
                  physics Physics {
                    density -1
                    mass 0.1
                  }
                  linearVelocity -3.614038460126229e-08 3.0422716739261375e-08 2.2050601991450536e-07
                  angularVelocity -6.241977693258531e-06 -4.715833253307122e-07 -4.4426089413017017e-07
                }
              }
              DEF sr8 HingeJoint {
                jointParameters HingeJointParameters {
                  position 452.9247071196548
                  axis 0 0.707107 0.707107
                  anchor -0.02 -0.03535 0.03535
                }
                endPoint Solid {
                  translation -0.02 -0.03535 0.03535
                  rotation -6.247038557098687e-16 0.7071067811865486 0.7071067811865464 0.5353650027245319
                  children [
                    USE r8
                  ]
                  name "sr8"
                  boundingObject USE r8
                  physics Physics {
                    density -1
                    mass 0.1
                  }
                  linearVelocity 2.7722134879911178e-08 4.7267027013341477e-07 -2.1961824963056744e-07
                  angularVelocity -6.241977691896052e-06 -4.6466637195968437e-07 -4.5114465774372225e-07
                }
              }
              USE WHEEL_TRANS
            ]
            boundingObject Pose {
              translation -0.02 0 0
              rotation 0 -1 0 1.5708
              children [
                DEF wheel1 Shape {
                  appearance PBRAppearance {
                    baseColor 0.8 0.8 0.8
                    transparency 0.12999999523162842
                    roughness 1
                    metalness 0
                    emissiveColor 0 1 0
                  }
                  geometry Cylinder {
                    height 0.02
                    radius 0.05
                  }
                }
              ]
            }
            physics Physics {
            }
            linearVelocity -4.209240101598903e-09 2.516154185553763e-07 4.4401294246589144e-10
            angularVelocity -6.241978073744098e-06 -3.926778382487547e-09 -9.096730352996276e-07
          }
        }
      ]
      name "wheel 2"
      boundingObject USE DUMMY
      physics Physics {
      }
    }
    DEF SOLID3 Solid {
      rotation 0 0 1 -2.3561950010791604
      children [
        DEF WHEEL3 HingeJoint {
          jointParameters HingeJointParameters {
            position -1.327236758416037e-06
            anchor -0.1 0 0
          }
          device [
            PositionSensor {
              name "pw1"
            }
            RotationalMotor {
              name "wheel1"
              maxVelocity 40
            }
          ]
          endPoint Solid {
            translation -0.18799999998986372 6.323850404085773e-10 1.2908761089938779e-05
            rotation -0.9999999376060535 0.0003532526510414244 6.733617973995579e-07 0.00390944090979623
            children [
              DEF sr1 HingeJoint {
                jointParameters HingeJointParameters {
                  position 210.87284800418138
                  axis 0 1 0
                  anchor -0.02 0 0.05
                }
                endPoint Solid {
                  translation -0.02 0 0.05
                  rotation 2.8281043308783136e-16 1 3.0236412318804467e-16 -2.7554524399245484
                  children [
                    USE r1
                  ]
                  name "sr1"
                  boundingObject USE r1
                  physics Physics {
                    density -1
                    mass 0.1
                  }
                  linearVelocity 5.95051026796491e-07 3.33885711243114e-07 9.238656387467108e-08
                  angularVelocity -3.623164786832705e-09 6.508988941760067e-06 -9.256664866377153e-07
                }
              }
              DEF sr2 HingeJoint {
                jointParameters HingeJointParameters {
                  position -524.1689156003263
                  axis 0 -0.707107 0.707107
                  anchor -0.02 0.03535 0.03535
                }
                endPoint Solid {
                  translation -0.02 0.03535 0.03535
                  rotation 0 -0.7071067811865476 0.7071067811865476 3.6186502027589915
                  children [
                    USE r2
                  ]
                  name "sr2"
                  boundingObject USE r2
                  physics Physics {
                    density -1
                    mass 0.1
                  }
                  linearVelocity 4.988239601439098e-07 3.079953119246919e-07 -1.3726705764940142e-07
                  angularVelocity -2.5796664238868364e-07 6.508987039077969e-06 -2.0163780049470304e-07
                }
              }
              DEF sr3 HingeJoint {
                jointParameters HingeJointParameters {
                  position -294.0344532679062
                  axis 0 1 0
                  anchor -0.02 0 -0.05
                }
                endPoint Solid {
                  translation -0.02 0 -0.05
                  rotation 0 -1 0 5.007929137645223
                  children [
                    USE r3
                  ]
                  name "sr3"
                  boundingObject USE r3
                  physics Physics {
                    density -1
                    mass 0.1
                  }
                  linearVelocity 2.6926855595018997e-08 3.804050544548832e-07 9.306166937510773e-08
                  angularVelocity -3.803818417169327e-05 6.508110290023117e-06 -7.769435208163887e-07
                }
              }
              DEF sr4 HingeJoint {
                jointParameters HingeJointParameters {
                  position 745.1432141694047
                  axis 0 -0.707107 0.707107
                  anchor -0.02 -0.03535 -0.03535
                }
                endPoint Solid {
                  translation -0.02 -0.03535 -0.03535
                  rotation 0 -0.7071067811865476 0.7071067811865476 3.727347922213496
                  children [
                    USE r4
                  ]
                  name "sr4"
                  boundingObject USE r4
                  physics Physics {
                    density -1
                    mass 0.1
                  }
                  linearVelocity 4.0568602457050584e-08 4.0634842835166367e-07 3.2458108995213676e-07
                  angularVelocity -2.6427712975096204e-07 6.508987012425946e-06 -1.952778079813969e-07
                }
              }
              DEF sr5 HingeJoint {
                jointParameters HingeJointParameters {
                  position -164.32123066067865
                  axis 0 0 1
                  anchor -0.02 0.05 0
                }
                endPoint Solid {
                  translation -0.02 0.05 0
                  rotation -1.1699717538771638e-15 1.5190468355032616e-15 0.9999999999999999 -0.9584126740094163
                  children [
                    USE r5
                  ]
                  name "sr5"
                  boundingObject USE r5
                  physics Physics {
                    density -1
                    mass 0.1
                  }
                  linearVelocity 2.684259253881312e-07 3.109013681547989e-07 -2.3169781399267285e-07
                  angularVelocity 4.658491582682066e-07 6.508987328904398e-06 -1.8042626119046011e-09
                }
              }
              DEF sr6 HingeJoint {
                jointParameters HingeJointParameters {
                  position 273.9872662698736
                  axis 0 0 1
                  anchor -0.02 -0.05 0
                }
                endPoint Solid {
                  translation -0.02 -0.05 0
                  rotation -7.615400008562902e-16 8.355706414821089e-17 0.9999999999999999 -2.472887246028225
                  children [
                    USE r6
                  ]
                  name "sr6"
                  boundingObject USE r6
                  physics Physics {
                    density -1
                    mass 0.1
                  }
                  linearVelocity 2.709666371990462e-07 4.034423661512834e-07 4.190118455760135e-07
                  angularVelocity 4.6584918528820896e-07 6.5089873296994865e-06 -1.8042627173986686e-09
                }
              }
              DEF sr7 HingeJoint {
                jointParameters HingeJointParameters {
                  position -337.7714670436428
                  axis 0 0.707107 0.707107
                  anchor -0.02 0.03535 -0.03535
                }
                endPoint Solid {
                  translation -0.02 0.03535 -0.03535
                  rotation 8.05540342373905e-17 0.7071067811865474 0.7071067811865478 1.5205395440548382
                  children [
                    USE r7
                  ]
                  name "sr7"
                  boundingObject USE r7
                  physics Physics {
                    density -1
                    mass 0.1
                  }
                  linearVelocity 3.8772332161190977e-08 3.409219496342596e-07 -1.3547063923977665e-07
                  angularVelocity 6.7337324490394e-07 6.508989172524497e-06 -7.179894235132374e-07
                }
              }
              DEF sr8 HingeJoint {
                jointParameters HingeJointParameters {
                  position 337.1906439595693
                  axis 0 0.707107 0.707107
                  anchor -0.02 -0.03535 0.03535
                }
                endPoint Solid {
                  translation -0.02 -0.03535 0.03535
                  rotation -1.919114326600746e-16 0.7071067811865475 0.7071067811865477 -2.101362628128368
                  children [
                    USE r8
                  ]
                  name "sr8"
                  boundingObject USE r8
                  physics Physics {
                    density -1
                    mass 0.1
                  }
                  linearVelocity 5.00620230396734e-07 3.73421793869925e-07 3.2278467114287994e-07
                  angularVelocity 7.114011583356482e-07 6.508989118658591e-06 -6.802573378257375e-07
                }
              }
              USE WHEEL_TRANS
            ]
            boundingObject Pose {
              translation -0.02 0 0
              rotation 0 -1 0 1.5708
              children [
                DEF wheel1 Shape {
                  appearance PBRAppearance {
                    baseColor 0.8 0.8 0.8
                    transparency 0.12999999523162842
                    roughness 1
                    metalness 0
                    emissiveColor 0 1 0
                  }
                  geometry Cylinder {
                    height 0.02
                    radius 0.05
                  }
                }
              ]
            }
            physics Physics {
            }
            linearVelocity 2.6977360539980804e-07 3.572715290613634e-07 9.368302406997052e-08
            angularVelocity 4.62234852577852e-07 6.508989525898062e-06 -9.274855098460034e-07
          }
        }
      ]
      name "wheel 3"
      boundingObject USE DUMMY
      physics Physics {
      }
    }
    DEF SOLID4 Solid {
      rotation 0 0 1 -0.7854003061004253
      children [
        DEF WHEEL4 HingeJoint {
          jointParameters HingeJointParameters {
            position 2.8476879169886336e-10
            anchor -0.1 0 0
          }
          device [
            PositionSensor {
              name "pw2"
            }
            RotationalMotor {
              name "wheel2"
              maxVelocity 40
            }
          ]
          endPoint Solid {
            translation -0.1879999999437038 -5.502930991518403e-10 1.2941999015673345e-05
            rotation -0.9999999372414817 0.000354283124531021 7.074920995256868e-07 0.003908094697331099
            children [
              DEF sr1 HingeJoint {
                jointParameters HingeJointParameters {
                  position -118.8536178135532
                  axis 0 1 0
                  anchor -0.02 0 0.05
                }
                endPoint Solid {
                  translation -0.02 0 0.05
                  rotation 0 -1 0 5.756282284320643
                  children [
                    USE r1
                  ]
                  name "sr1"
                  boundingObject USE r1
                  physics Physics {
                    density -1
                    mass 0.1
                  }
                  linearVelocity -4.225498943061567e-09 7.76785847314587e-07 -2.3666453952182303e-09
                  angularVelocity -6.076876115929577e-06 -3.551552689867244e-09 -9.105337558504337e-07
                }
              }
              DEF sr2 HingeJoint {
                jointParameters HingeJointParameters {
                  position -173.12626693489975
                  axis 0 -0.707107 0.707107
                  anchor -0.02 0.03535 0.03535
                }
                endPoint Solid {
                  translation -0.02 0.03535 0.03535
                  rotation -3.5972965273806816e-16 -0.7071067811865476 0.7071067811865472 2.8029216661286656
                  children [
                    USE r2
                  ]
                  name "sr2"
                  boundingObject USE r2
                  physics Physics {
                    density -1
                    mass 0.1
                  }
                  linearVelocity 2.7957586209776244e-08 6.869464143938904e-07 -2.1677393304386855e-07
                  angularVelocity -6.076877273317781e-06 -4.307861724079297e-07 -4.802729236689054e-07
                }
              }
              DEF sr3 HingeJoint {
                jointParameters HingeJointParameters {
                  position 106.13970052100873
                  axis 0 1 0
                  anchor -0.02 0 -0.05
                }
                endPoint Solid {
                  translation -0.02 0 -0.05
                  rotation 0 1 0 5.608735606135351
                  children [
                    USE r3
                  ]
                  name "sr3"
                  boundingObject USE r3
                  physics Physics {
                    density -1
                    mass 0.1
                  }
                  linearVelocity -4.193627264754701e-09 9.512920854010135e-08 2.228901488904966e-12
                  angularVelocity -6.077605850780053e-06 -4.2504708693595963e-07 -9.086792411650806e-07
                }
              }
              DEF sr4 HingeJoint {
                jointParameters HingeJointParameters {
                  position 342.2475934179364
                  axis 0 -0.707107 0.707107
                  anchor -0.02 -0.03535 -0.03535
                }
                endPoint Solid {
                  translation -0.02 -0.03535 -0.03535
                  rotation -1.1136341919173957e-16 -0.7071067811865475 0.7071067811865477 2.9555868302387434
                  children [
                    USE r4
                  ]
                  name "sr4"
                  boundingObject USE r4
                  physics Physics {
                    density -1
                    mass 0.1
                  }
                  linearVelocity -3.637680457608594e-08 2.591144256483629e-07 2.1441431292678697e-07
                  angularVelocity -6.076877282500125e-06 -4.3953120952753764e-07 -4.714593125622027e-07
                }
              }
              DEF sr5 HingeJoint {
                jointParameters HingeJointParameters {
                  position 148.49656521624223
                  axis 0 0 1
                  anchor -0.02 0.05 0
                }
                endPoint Solid {
                  translation -0.02 0.05 0
                  rotation -9.299370312620455e-16 1.9504571084695464e-16 1 -2.2998821560678495
                  children [
                    USE r5
                  ]
                  name "sr5"
                  boundingObject USE r5
                  physics Physics {
                    density -1
                    mass 0.1
                  }
                  linearVelocity 4.130447335121371e-08 4.7184354315303594e-07 -3.0493515865258943e-07
                  angularVelocity -6.076877998347087e-06 -3.181554646423011e-10 -1.1296876582925928e-11
                }
              }
              DEF sr6 HingeJoint {
                jointParameters HingeJointParameters {
                  position -136.86575133947642
                  axis 0 0 1
                  anchor -0.02 -0.05 0
                }
                endPoint Solid {
                  translation -0.02 -0.05 0
                  rotation -4.489722743301865e-16 -1.0232001556628407e-15 1 1.36432541847448
                  children [
                    USE r6
                  ]
                  name "sr6"
                  boundingObject USE r6
                  physics Physics {
                    density -1
                    mass 0.1
                  }
                  linearVelocity -4.9723669146603344e-08 4.742172746414367e-07 3.0257553822465507e-07
                  angularVelocity -6.076877997825753e-06 -3.1814827142556486e-10 -1.1296904662291462e-11
                }
              }
              DEF sr7 HingeJoint {
                jointParameters HingeJointParameters {
                  position 12.54382658284056
                  axis 0 0.707107 0.707107
                  anchor -0.02 0.03535 -0.03535
                }
                endPoint Solid {
                  translation -0.02 0.03535 -0.03535
                  rotation 1.3655665390598165e-14 -0.7071067811865306 -0.7071067811865646 0.022544031518605227
                  children [
                    USE r7
                  ]
                  name "sr7"
                  boundingObject USE r7
                  physics Physics {
                    density -1
                    mass 0.1
                  }
                  linearVelocity 2.7980094155033936e-08 2.5743619937303483e-07 -2.150957492386271e-07
                  angularVelocity -6.076876776245609e-06 4.5180412654255403e-07 -4.583995747374708e-07
                }
              }
              DEF sr8 HingeJoint {
                jointParameters HingeJointParameters {
                  position -30.28982012817961
                  axis 0 0.707107 0.707107
                  anchor -0.02 -0.03535 0.03535
                }
                endPoint Solid {
                  translation -0.02 -0.03535 0.03535
                  rotation 0 -0.7071067811865475 -0.7071067811865475 5.157078899461264
                  children [
                    USE r8
                  ]
                  name "sr8"
                  boundingObject USE r8
                  physics Physics {
                    density -1
                    mass 0.1
                  }
                  linearVelocity -3.639928796811541e-08 6.886246184184276e-07 2.1273612906823197e-07
                  angularVelocity -6.0768767506346944e-06 4.360181900000256e-07 -4.740626410615624e-07
                }
              }
              USE WHEEL_TRANS
            ]
            boundingObject Pose {
              translation -0.02 0 0
              rotation 0 -1 0 1.5708
              children [
                DEF wheel1 Shape {
                  appearance PBRAppearance {
                    baseColor 0.8 0.8 0.8
                    transparency 0.12999999523162842
                    roughness 1
                    metalness 0
                    emissiveColor 0 1 0
                  }
                  geometry Cylinder {
                    height 0.02
                    radius 0.05
                  }
                }
              ]
            }
            physics Physics {
            }
            linearVelocity -4.209724171656749e-09 4.731636388653913e-07 -1.1801507798660671e-09
            angularVelocity -6.076876217316591e-06 -3.875656031900596e-09 -9.105325033395563e-07
          }
        }
      ]
      name "wheel 4"
      boundingObject USE DUMMY
      physics Physics {
      }
    }
    Camera {
      translation 0 0 0.4
      rotation 0 1 0 1.5708
      fieldOfView 3.14
      width 640
      height 640
      projection "spherical"
    }
    DEF BODY_TRANS Pose {
      translation 0 0 0.04
      children [
        Shape {
          appearance PBRAppearance {
            baseColor 0.564706 0.933333 0.564706
            roughness 1
            metalness 0
          }
          geometry Box {
            size 0.25 0.25 0.1
          }
        }
      ]
    }
  ]
  name "robot(1)"
  boundingObject USE BODY_TRANS
  physics Physics {
  }
  controller "<none>"
  linearVelocity -4.365774962996764e-09 3.398348719027351e-07 -3.716360750819084e-10
  angularVelocity 4.6247314986239413e-07 -3.880366308004054e-09 -9.188610950100712e-07
}
